Workbook
Name クライテリア本文: 'アセスメント'!$A$2:$E$330

Sheet 概要

Sheet アセスメント
E1: =progressbar!E9 -> progress :□□□□□□□□□□□□□□□□□□□□ 0/320 | F1: 未入力の項目または入力エラーの項目があります。
B2: theme | C2: category | D2: point of view | E2: criterion | F2: yes | G2: no | H2: but | I2: remarks
A3: =criteria!A2 -> 1 | B3: =criteria!B2 -> TEAM-1-1 | C3: =criteria!E2 -> チーム構成と権限委譲 | D3: =criteria!D2 -> メトリクスの計測 | E3: =hyperlink(vlookup(B3,link!$B$2:$D$332,3,FALSE),criteria!F2) -> システムを開発する１チームの構成人数は、3人以上10人以下か。（ピザ2枚ルール） | F3: FALSE | G3: FALSE | H3: FALSE
A4: =criteria!A3 -> 2 | B4: =criteria!B3 -> TEAM-1-2 | D4: =criteria!D3 -> 学習と改善 | E4: =hyperlink(vlookup(B4,link!$B$2:$D$332,3,FALSE),criteria!F3) -> ある特定の人物に属人化した仕事を洗い出し、減らしていく仕組みがチームにあるか。 | F4: FALSE | G4: FALSE | H4: FALSE
A5: =criteria!A4 -> 3 | B5: =criteria!B4 -> TEAM-1-3 | D5: =criteria!D4 -> プラクティス | E5: =hyperlink(vlookup(B5,link!$B$2:$D$332,3,FALSE),criteria!F4) -> チームとチームメンバーの権限について、RACI図やデリゲーションポーカーなどによって、可視化され共有されているか。 | F5: FALSE | G5: FALSE | H5: FALSE
A6: =criteria!A5 -> 4 | B6: =criteria!B5 -> TEAM-1-4 | D6: =criteria!D5 -> プラクティス | E6: =hyperlink(vlookup(B6,link!$B$2:$D$332,3,FALSE),criteria!F5) -> チームは価値提供をするのに必要な全職能のメンバーで構成されているか。(フィーチャーチーム) | F6: FALSE | G6: FALSE | H6: FALSE
A7: =criteria!A6 -> 5 | B7: =criteria!B6 -> TEAM-1-5 | D7: =criteria!D6 -> プラクティス | E7: =hyperlink(vlookup(B7,link!$B$2:$D$332,3,FALSE),criteria!F6) -> チームおよびチームリーダーは、チームのミッションのために必要な外部のリソースを調達するための予算や権限をもっているか。 | F7: FALSE | G7: FALSE | H7: FALSE
A8: =criteria!A7 -> 6 | B8: =criteria!B7 -> TEAM-1-6 | D8: =criteria!D7 -> アンチパターン | E8: =hyperlink(vlookup(B8,link!$B$2:$D$332,3,FALSE),criteria!F7) -> チームという単位は存在するが、メンバーのそれぞれのやっている仕事の内容をよく知らないし、代わりにやることもできない。 | F8: FALSE | G8: FALSE | H8: FALSE
A9: =criteria!A8 -> 7 | B9: =criteria!B8 -> TEAM-1-7 | D9: =criteria!D8 -> アンチパターン | E9: =hyperlink(vlookup(B9,link!$B$2:$D$332,3,FALSE),criteria!F8) -> チームリーダーが複数のチームやプロジェクトを兼務しており、自チームのためにすべての時間を使うことができない。 | F9: FALSE | G9: FALSE | H9: FALSE
A10: =criteria!A9 -> 8 | B10: =criteria!B9 -> TEAM-1-8 | D10: =criteria!D9 -> アンチパターン | E10: =hyperlink(vlookup(B10,link!$B$2:$D$332,3,FALSE),criteria!F9) -> チームリーダーがメンバーに権限委譲できておらず、ボトルネックになっている。 | F10: FALSE | G10: FALSE | H10: FALSE
A11: =criteria!A10 -> 9 | B11: =criteria!B10 -> TEAM-2-1 | C11: =criteria!E10 -> チームビルディング | D11: =criteria!D10 -> メトリクスの計測 | E11: =hyperlink(vlookup(B11,link!$B$2:$D$332,3,FALSE),criteria!F10) -> チームは少なくとも半年以上継続して存在しているか。 | F11: FALSE | G11: FALSE | H11: FALSE
A12: =criteria!A11 -> 10 | B12: =criteria!B11 -> TEAM-2-2 | D12: =criteria!D11 -> 学習と改善 | E12: =hyperlink(vlookup(B12,link!$B$2:$D$332,3,FALSE),criteria!F11) -> チームは月に一度以上の頻度で仕事のふりかえりをおこなっており、その際にプロジェクト憲章またはインセプションデッキを見返して目的を再確認しているか。 | F12: FALSE | G12: FALSE | H12: FALSE
A13: =criteria!A12 -> 11 | B13: =criteria!B12 -> TEAM-2-3 | D13: =criteria!D12 -> プラクティス | E13: =hyperlink(vlookup(B13,link!$B$2:$D$332,3,FALSE),criteria!F12) -> インセプションデッキまたはプロジェクト憲章を作成し、チームの存在理由についてチーム全員が把握しているか。 | F13: FALSE | G13: FALSE | H13: FALSE
A14: =criteria!A13 -> 12 | B14: =criteria!B13 -> TEAM-2-4 | D14: =criteria!D13 -> プラクティス | E14: =hyperlink(vlookup(B14,link!$B$2:$D$332,3,FALSE),criteria!F13) -> 新しくチームに参画するメンバー用のオンボーディング・デック（チームの一員として働き始めるための、価値観・実務・スキル・相互理解のための明文化されたドキュメント集）が存在するか。 | F14: FALSE | G14: FALSE | H14: FALSE
A15: =criteria!A14 -> 13 | B15: =criteria!B14 -> TEAM-2-5 | D15: =criteria!D14 -> プラクティス | E15: =hyperlink(vlookup(B15,link!$B$2:$D$332,3,FALSE),criteria!F14) -> チームメンバー全員で定期的にカジュアルにコミュニケーションをとる場がある（ランチ、ディナー、レクレーション等） | F15: FALSE | G15: FALSE | H15: FALSE
A16: =criteria!A15 -> 14 | B16: =criteria!B15 -> TEAM-2-6 | D16: =criteria!D15 -> アンチパターン | E16: =hyperlink(vlookup(B16,link!$B$2:$D$332,3,FALSE),criteria!F15) -> オンボーディングプログラムが、文章を読むだけのものになっており、ハンズオンやミッション理解の伴わない形骸化したものになっている。 | F16: FALSE | G16: FALSE | H16: FALSE
A17: =criteria!A16 -> 15 | B17: =criteria!B16 -> TEAM-2-7 | D17: =criteria!D16 -> アンチパターン | E17: =hyperlink(vlookup(B17,link!$B$2:$D$332,3,FALSE),criteria!F16) -> 1年以上チームのやることが変わっておらず、チームメンバーも固定されている。 | F17: FALSE | G17: FALSE | H17: FALSE
A18: =criteria!A17 -> 16 | B18: =criteria!B17 -> TEAM-2-8 | D18: =criteria!D17 -> アンチパターン | E18: =hyperlink(vlookup(B18,link!$B$2:$D$332,3,FALSE),criteria!F17) -> チーム内でチームミッションの改善に関係する議論がどんな理由であれ発生していない。 | F18: FALSE | G18: FALSE | H18: FALSE
A19: =criteria!A18 -> 17 | B19: =criteria!B18 -> TEAM-3-1 | C19: =criteria!E18 -> 心理的安全性 | D19: =criteria!D18 -> メトリクスの計測 | E19: =hyperlink(vlookup(B19,link!$B$2:$D$332,3,FALSE),criteria!F18) -> チームメンバーの心理的安全性を測る指標があり、定期的に計測しているか。 | F19: FALSE | G19: FALSE | H19: FALSE
A20: =criteria!A19 -> 18 | B20: =criteria!B19 -> TEAM-3-2 | D20: =criteria!D19 -> 学習と改善 | E20: =hyperlink(vlookup(B20,link!$B$2:$D$332,3,FALSE),criteria!F19) -> 1on1や、落ち着いた場面でのカジュアルな雑談を含む直接業務に関わらないキャリアやタスクの壁打ちを、月に1度程度は実施しているか。 | F20: FALSE | G20: FALSE | H20: FALSE
A21: =criteria!A20 -> 19 | B21: =criteria!B20 -> TEAM-3-3 | D21: =criteria!D20 -> プラクティス | E21: =hyperlink(vlookup(B21,link!$B$2:$D$332,3,FALSE),criteria!F20) -> チームメンバーの行動/発言を明示的に承認行為をおこなう習慣があるか。（成果ではなく行動したこと自体に対して、拍手する・感謝を述べるなど） | F21: FALSE | G21: FALSE | H21: FALSE
A22: =criteria!A21 -> 20 | B22: =criteria!B21 -> TEAM-3-4 | D22: =criteria!D21 -> プラクティス | E22: =hyperlink(vlookup(B22,link!$B$2:$D$332,3,FALSE),criteria!F21) -> チームメンバー間で挨拶をしたり、雑談をする習慣はあるか。 | F22: FALSE | G22: FALSE | H22: FALSE
A23: =criteria!A22 -> 21 | B23: =criteria!B22 -> TEAM-3-5 | D23: =criteria!D22 -> プラクティス | E23: =hyperlink(vlookup(B23,link!$B$2:$D$332,3,FALSE),criteria!F22) -> チームの不安や不満などを可視化し、吸い上げるための仕組みを持っているか。 | F23: FALSE | G23: FALSE | H23: FALSE
A24: =criteria!A23 -> 22 | B24: =criteria!B23 -> TEAM-3-6 | D24: =criteria!D23 -> アンチパターン | E24: =hyperlink(vlookup(B24,link!$B$2:$D$332,3,FALSE),criteria!F23) -> ミッションや共通のゴール設定をしないまま意見を集め、課題のためというよりも個人のための意見しか出てこない状況になっている。 | F24: FALSE | G24: FALSE | H24: FALSE
A25: =criteria!A24 -> 23 | B25: =criteria!B24 -> TEAM-3-7 | D25: =criteria!D24 -> アンチパターン | E25: =hyperlink(vlookup(B25,link!$B$2:$D$332,3,FALSE),criteria!F24) -> 心理的安全性を仲の良さと捉えて、事業のための意見ではなく、仲良くすることが目的化しているため、意見を封殺してしまう。 | F25: FALSE | G25: FALSE | H25: FALSE
A26: =criteria!A25 -> 24 | B26: =criteria!B25 -> TEAM-3-8 | D26: =criteria!D25 -> アンチパターン | E26: =hyperlink(vlookup(B26,link!$B$2:$D$332,3,FALSE),criteria!F25) -> 事業目標や納期目標に対して、威圧的なマネジメントや権威的な命令を繰り返したことで、意見が出てこない状況になっている。 | F26: FALSE | G26: FALSE | H26: FALSE
A27: =criteria!A26 -> 25 | B27: =criteria!B26 -> TEAM-4-1 | C27: =criteria!E26 -> タスクマネジメント | D27: =criteria!D26 -> メトリクスの計測 | E27: =hyperlink(vlookup(B27,link!$B$2:$D$332,3,FALSE),criteria!F26) -> アイデアレベルの要望や構想から、要件に落ちるまでのリードタイムは計測されているか。 | F27: FALSE | G27: FALSE | H27: FALSE
A28: =criteria!A27 -> 26 | B28: =criteria!B27 -> TEAM-4-2 | D28: =criteria!D27 -> 学習と改善 | E28: =hyperlink(vlookup(B28,link!$B$2:$D$332,3,FALSE),criteria!F27) -> 仕事を始めるための定義と、完了するための定義はチームやステークホルダーで定期的に見直されているか。 | F28: FALSE | G28: FALSE | H28: FALSE
A29: =criteria!A28 -> 27 | B29: =criteria!B28 -> TEAM-4-3 | D29: =criteria!D28 -> プラクティス | E29: =hyperlink(vlookup(B29,link!$B$2:$D$332,3,FALSE),criteria!F28) -> 上長やステークホルダーを含め、共通のタスク管理ツールを利用しており、プロジェクトの状況を可視化したダッシュボードに常にアクセス可能か。 | F29: FALSE | G29: FALSE | H29: FALSE
A30: =criteria!A29 -> 28 | B30: =criteria!B29 -> TEAM-4-4 | D30: =criteria!D29 -> プラクティス | E30: =hyperlink(vlookup(B30,link!$B$2:$D$332,3,FALSE),criteria!F29) -> チームが仕事を始めるために必要な課題やタスクの粒度について、明文化されたフォーマットが存在するか。 | F30: FALSE | G30: FALSE | H30: FALSE
A31: =criteria!A30 -> 29 | B31: =criteria!B30 -> TEAM-4-5 | D31: =criteria!D30 -> プラクティス | E31: =hyperlink(vlookup(B31,link!$B$2:$D$332,3,FALSE),criteria!F30) -> チームのタスクに関して、「完成(完了)の定義(Definition of DONE)」が存在するか。 | F31: FALSE | G31: FALSE | H31: FALSE
A32: =criteria!A31 -> 30 | B32: =criteria!B31 -> TEAM-4-6 | D32: =criteria!D31 -> アンチパターン | E32: =hyperlink(vlookup(B32,link!$B$2:$D$332,3,FALSE),criteria!F31) -> 他部署からの依頼が明確なタスクツールではなく、担当者へのダイレクトメール/メッセージ/口頭など透明性のない形で行われている。 | F32: FALSE | G32: FALSE | H32: FALSE
A33: =criteria!A32 -> 31 | B33: =criteria!B32 -> TEAM-4-7 | D33: =criteria!D32 -> アンチパターン | E33: =hyperlink(vlookup(B33,link!$B$2:$D$332,3,FALSE),criteria!F32) -> どのチームタスクであるかが曖昧なとき、ボールが落ちないようにするための仕組みや文化が存在しない。 | F33: FALSE | G33: FALSE | H33: FALSE
A34: =criteria!A33 -> 32 | B34: =criteria!B33 -> TEAM-4-8 | D34: =criteria!D33 -> アンチパターン | E34: =hyperlink(vlookup(B34,link!$B$2:$D$332,3,FALSE),criteria!F33) -> どのチームタスクであるか曖昧な仕事が発生したあとに、事後検証（ポストモーテム）が行われず都度話し合いで解決している。 | F34: FALSE | G34: FALSE | H34: FALSE
A35: =criteria!A34 -> 33 | B35: =criteria!B34 -> TEAM-5-1 | C35: =criteria!E34 -> 透明性ある目標管理 | D35: =criteria!D34 -> メトリクスの計測 | E35: =hyperlink(vlookup(B35,link!$B$2:$D$332,3,FALSE),criteria!F34) -> １年後などのチームとプロダクトの目指す姿が、言語化され、いくつかの計測可能な指標により明晰化されているか。 | F35: FALSE | G35: FALSE | H35: FALSE
A36: =criteria!A35 -> 34 | B36: =criteria!B35 -> TEAM-5-2 | D36: =criteria!D35 -> 学習と改善 | E36: =hyperlink(vlookup(B36,link!$B$2:$D$332,3,FALSE),criteria!F35) -> 仮説的な目標に対して、うまくいかなかった際にチームとして「学んだこと」を言語化・他チームへ公開・学習しているか。 | F36: FALSE | G36: FALSE | H36: FALSE
A37: =criteria!A36 -> 35 | B37: =criteria!B36 -> TEAM-5-3 | D37: =criteria!D36 -> プラクティス | E37: =hyperlink(vlookup(B37,link!$B$2:$D$332,3,FALSE),criteria!F36) -> 四半期にフォーカスすべき目標が言語化され、いくつかの計測可能な指標によって明晰化されているか。 | F37: FALSE | G37: FALSE | H37: FALSE
A38: =criteria!A37 -> 36 | B38: =criteria!B37 -> TEAM-5-4 | D38: =criteria!D37 -> プラクティス | E38: =hyperlink(vlookup(B38,link!$B$2:$D$332,3,FALSE),criteria!F37) -> フォーカスすべき目標に対して、どのようにアプローチするのかの計画をチームで共有しているか。 | F38: FALSE | G38: FALSE | H38: FALSE
A39: =criteria!A38 -> 37 | B39: =criteria!B38 -> TEAM-5-5 | D39: =criteria!D38 -> プラクティス | E39: =hyperlink(vlookup(B39,link!$B$2:$D$332,3,FALSE),criteria!F38) -> ビジネス上、重要なマイルストーンとそのスケジュールをチームで常に共有し、その進捗を確認しているか。 | F39: FALSE | G39: FALSE | H39: FALSE
A40: =criteria!A39 -> 38 | B40: =criteria!B39 -> TEAM-5-6 | D40: =criteria!D39 -> アンチパターン | E40: =hyperlink(vlookup(B40,link!$B$2:$D$332,3,FALSE),criteria!F39) -> 目標管理が強く評価制度に結びついているため、ストレッチしたゴール設定をすることが難しくなっている。 | F40: FALSE | G40: FALSE | H40: FALSE
...

Sheet 可視化
C1: 未入力の項目または入力エラーの項目があります。
A2: テーマ | B2: No | C2: カテゴリー | L2: 合計 | M2: カテゴリ | N2: 偏差値 | O2: レイティング
A3: チーム | B3: =category!B2 -> 1 | C3: =category!C2 -> チーム構成と権限委譲 | D3: =indirect("counting!L"& ((row()-3)*8 + COLUMN() -2)) -> - | E3: =indirect("counting!L"& ((row()-3)*8 + COLUMN() -2)) -> - | F3: =indirect("counting!L"& ((row()-3)*8 + COLUMN() -2)) -> - | G3: =indirect("counting!L"& ((row()-3)*8 + COLUMN() -2)) -> - | H3: =indirect("counting!L"& ((row()-3)*8 + COLUMN() -2)) -> - | I3: =indirect("counting!L"& ((row()-3)*8 + COLUMN() -2)) -> - | J3: =indirect("counting!L"& ((row()-3)*8 + COLUMN() -2)) -> - | K3: =indirect("counting!L"& ((row()-3)*8 + COLUMN() -2)) -> - | L3: =sum(D3:K3) -> 0 | M3: =sum(L3:L10) -> 0 | N3: =((M3-stats!B2)/stats!C2)*10+50 -> 7.4941452 | O3: =vlookup(N3,rating!$B$2:$D$13,3,TRUE) -> DD
B4: =category!B3 -> 2 | C4: =category!C3 -> チームビルディング | D4: =indirect("counting!L"& ((row()-3)*8 + COLUMN() -2)) -> - | E4: =indirect("counting!L"& ((row()-3)*8 + COLUMN() -2)) -> - | F4: =indirect("counting!L"& ((row()-3)*8 + COLUMN() -2)) -> - | G4: =indirect("counting!L"& ((row()-3)*8 + COLUMN() -2)) -> - | H4: =indirect("counting!L"& ((row()-3)*8 + COLUMN() -2)) -> - | I4: =indirect("counting!L"& ((row()-3)*8 + COLUMN() -2)) -> - | J4: =indirect("counting!L"& ((row()-3)*8 + COLUMN() -2)) -> - | K4: =indirect("counting!L"& ((row()-3)*8 + COLUMN() -2)) -> - | L4: =sum(D4:K4) -> 0
B5: =category!B4 -> 3 | C5: =category!C4 -> 心理的安全性 | D5: =indirect("counting!L"& ((row()-3)*8 + COLUMN() -2)) -> - | E5: =indirect("counting!L"& ((row()-3)*8 + COLUMN() -2)) -> - | F5: =indirect("counting!L"& ((row()-3)*8 + COLUMN() -2)) -> - | G5: =indirect("counting!L"& ((row()-3)*8 + COLUMN() -2)) -> - | H5: =indirect("counting!L"& ((row()-3)*8 + COLUMN() -2)) -> - | I5: =indirect("counting!L"& ((row()-3)*8 + COLUMN() -2)) -> - | J5: =indirect("counting!L"& ((row()-3)*8 + COLUMN() -2)) -> - | K5: =indirect("counting!L"& ((row()-3)*8 + COLUMN() -2)) -> - | L5: =sum(D5:K5) -> 0
B6: =category!B5 -> 4 | C6: =category!C5 -> タスクマネジメント | D6: =indirect("counting!L"& ((row()-3)*8 + COLUMN() -2)) -> - | E6: =indirect("counting!L"& ((row()-3)*8 + COLUMN() -2)) -> - | F6: =indirect("counting!L"& ((row()-3)*8 + COLUMN() -2)) -> - | G6: =indirect("counting!L"& ((row()-3)*8 + COLUMN() -2)) -> - | H6: =indirect("counting!L"& ((row()-3)*8 + COLUMN() -2)) -> - | I6: =indirect("counting!L"& ((row()-3)*8 + COLUMN() -2)) -> - | J6: =indirect("counting!L"& ((row()-3)*8 + COLUMN() -2)) -> - | K6: =indirect("counting!L"& ((row()-3)*8 + COLUMN() -2)) -> - | L6: =sum(D6:K6) -> 0
B7: =category!B6 -> 5 | C7: =category!C6 -> 透明性ある目標管理 | D7: =indirect("counting!L"& ((row()-3)*8 + COLUMN() -2)) -> - | E7: =indirect("counting!L"& ((row()-3)*8 + COLUMN() -2)) -> - | F7: =indirect("counting!L"& ((row()-3)*8 + COLUMN() -2)) -> - | G7: =indirect("counting!L"& ((row()-3)*8 + COLUMN() -2)) -> - | H7: =indirect("counting!L"& ((row()-3)*8 + COLUMN() -2)) -> - | I7: =indirect("counting!L"& ((row()-3)*8 + COLUMN() -2)) -> - | J7: =indirect("counting!L"& ((row()-3)*8 + COLUMN() -2)) -> - | K7: =indirect("counting!L"& ((row()-3)*8 + COLUMN() -2)) -> - | L7: =sum(D7:K7) -> 0
B8: =category!B7 -> 6 | C8: =category!C7 -> 経験主義的な見積りと計画 | D8: =indirect("counting!L"& ((row()-3)*8 + COLUMN() -2)) -> - | E8: =indirect("counting!L"& ((row()-3)*8 + COLUMN() -2)) -> - | F8: =indirect("counting!L"& ((row()-3)*8 + COLUMN() -2)) -> - | G8: =indirect("counting!L"& ((row()-3)*8 + COLUMN() -2)) -> - | H8: =indirect("counting!L"& ((row()-3)*8 + COLUMN() -2)) -> - | I8: =indirect("counting!L"& ((row()-3)*8 + COLUMN() -2)) -> - | J8: =indirect("counting!L"& ((row()-3)*8 + COLUMN() -2)) -> - | K8: =indirect("counting!L"& ((row()-3)*8 + COLUMN() -2)) -> - | L8: =sum(D8:K8) -> 0
B9: =category!B8 -> 7 | C9: =category!C8 -> ふりかえり習慣 | D9: =indirect("counting!L"& ((row()-3)*8 + COLUMN() -2)) -> - | E9: =indirect("counting!L"& ((row()-3)*8 + COLUMN() -2)) -> - | F9: =indirect("counting!L"& ((row()-3)*8 + COLUMN() -2)) -> - | G9: =indirect("counting!L"& ((row()-3)*8 + COLUMN() -2)) -> - | H9: =indirect("counting!L"& ((row()-3)*8 + COLUMN() -2)) -> - | I9: =indirect("counting!L"& ((row()-3)*8 + COLUMN() -2)) -> - | J9: =indirect("counting!L"& ((row()-3)*8 + COLUMN() -2)) -> - | K9: =indirect("counting!L"& ((row()-3)*8 + COLUMN() -2)) -> - | L9: =sum(D9:K9) -> 0
B10: =category!B9 -> 8 | C10: =category!C9 -> バリューストリーム最適化 | D10: =indirect("counting!L"& ((row()-3)*8 + COLUMN() -2)) -> - | E10: =indirect("counting!L"& ((row()-3)*8 + COLUMN() -2)) -> - | F10: =indirect("counting!L"& ((row()-3)*8 + COLUMN() -2)) -> - | G10: =indirect("counting!L"& ((row()-3)*8 + COLUMN() -2)) -> - | H10: =indirect("counting!L"& ((row()-3)*8 + COLUMN() -2)) -> - | I10: =indirect("counting!L"& ((row()-3)*8 + COLUMN() -2)) -> - | J10: =indirect("counting!L"& ((row()-3)*8 + COLUMN() -2)) -> - | K10: =indirect("counting!L"& ((row()-3)*8 + COLUMN() -2)) -> - | L10: =sum(D10:K10) -> 0
A11: システム | B11: =category!B10 -> 1 | C11: =category!C10 -> バージョン管理 | D11: =indirect("counting!L"& ((row()-3)*8 + COLUMN() -2)) -> - | E11: =indirect("counting!L"& ((row()-3)*8 + COLUMN() -2)) -> - | F11: =indirect("counting!L"& ((row()-3)*8 + COLUMN() -2)) -> - | G11: =indirect("counting!L"& ((row()-3)*8 + COLUMN() -2)) -> - | H11: =indirect("counting!L"& ((row()-3)*8 + COLUMN() -2)) -> - | I11: =indirect("counting!L"& ((row()-3)*8 + COLUMN() -2)) -> - | J11: =indirect("counting!L"& ((row()-3)*8 + COLUMN() -2)) -> - | K11: =indirect("counting!L"& ((row()-3)*8 + COLUMN() -2)) -> - | L11: =sum(D11:K11) -> 0 | M11: =sum(L11:L18) -> 0 | N11: =((M11-stats!B3)/stats!C3)*10+50 -> 16.163142 | O11: =vlookup(N11,rating!$B$2:$D$13,3,TRUE) -> DD
B12: =category!B11 -> 2 | C12: =category!C11 -> ソースコードの明確さ | D12: =indirect("counting!L"& ((row()-3)*8 + COLUMN() -2)) -> - | E12: =indirect("counting!L"& ((row()-3)*8 + COLUMN() -2)) -> - | F12: =indirect("counting!L"& ((row()-3)*8 + COLUMN() -2)) -> - | G12: =indirect("counting!L"& ((row()-3)*8 + COLUMN() -2)) -> - | H12: =indirect("counting!L"& ((row()-3)*8 + COLUMN() -2)) -> - | I12: =indirect("counting!L"& ((row()-3)*8 + COLUMN() -2)) -> - | J12: =indirect("counting!L"& ((row()-3)*8 + COLUMN() -2)) -> - | K12: =indirect("counting!L"& ((row()-3)*8 + COLUMN() -2)) -> - | L12: =sum(D12:K12) -> 0
B13: =category!B12 -> 3 | C13: =category!C12 -> 継続的インテグレーション | D13: =indirect("counting!L"& ((row()-3)*8 + COLUMN() -2)) -> - | E13: =indirect("counting!L"& ((row()-3)*8 + COLUMN() -2)) -> - | F13: =indirect("counting!L"& ((row()-3)*8 + COLUMN() -2)) -> - | G13: =indirect("counting!L"& ((row()-3)*8 + COLUMN() -2)) -> - | H13: =indirect("counting!L"& ((row()-3)*8 + COLUMN() -2)) -> - | I13: =indirect("counting!L"& ((row()-3)*8 + COLUMN() -2)) -> - | J13: =indirect("counting!L"& ((row()-3)*8 + COLUMN() -2)) -> - | K13: =indirect("counting!L"& ((row()-3)*8 + COLUMN() -2)) -> - | L13: =sum(D13:K13) -> 0
B14: =category!B13 -> 4 | C14: =category!C13 -> 継続的デプロイ | D14: =indirect("counting!L"& ((row()-3)*8 + COLUMN() -2)) -> - | E14: =indirect("counting!L"& ((row()-3)*8 + COLUMN() -2)) -> - | F14: =indirect("counting!L"& ((row()-3)*8 + COLUMN() -2)) -> - | G14: =indirect("counting!L"& ((row()-3)*8 + COLUMN() -2)) -> - | H14: =indirect("counting!L"& ((row()-3)*8 + COLUMN() -2)) -> - | I14: =indirect("counting!L"& ((row()-3)*8 + COLUMN() -2)) -> - | J14: =indirect("counting!L"& ((row()-3)*8 + COLUMN() -2)) -> - | K14: =indirect("counting!L"& ((row()-3)*8 + COLUMN() -2)) -> - | L14: =sum(D14:K14) -> 0
B15: =category!B14 -> 5 | C15: =category!C14 -> API駆動開発 | D15: =indirect("counting!L"& ((row()-3)*8 + COLUMN() -2)) -> - | E15: =indirect("counting!L"& ((row()-3)*8 + COLUMN() -2)) -> - | F15: =indirect("counting!L"& ((row()-3)*8 + COLUMN() -2)) -> - | G15: =indirect("counting!L"& ((row()-3)*8 + COLUMN() -2)) -> - | H15: =indirect("counting!L"& ((row()-3)*8 + COLUMN() -2)) -> - | I15: =indirect("counting!L"& ((row()-3)*8 + COLUMN() -2)) -> - | J15: =indirect("counting!L"& ((row()-3)*8 + COLUMN() -2)) -> - | K15: =indirect("counting!L"& ((row()-3)*8 + COLUMN() -2)) -> - | L15: =sum(D15:K15) -> 0
B16: =category!B15 -> 6 | C16: =category!C15 -> 疎結合アーキテクチャ | D16: =indirect("counting!L"& ((row()-3)*8 + COLUMN() -2)) -> - | E16: =indirect("counting!L"& ((row()-3)*8 + COLUMN() -2)) -> - | F16: =indirect("counting!L"& ((row()-3)*8 + COLUMN() -2)) -> - | G16: =indirect("counting!L"& ((row()-3)*8 + COLUMN() -2)) -> - | H16: =indirect("counting!L"& ((row()-3)*8 + COLUMN() -2)) -> - | I16: =indirect("counting!L"& ((row()-3)*8 + COLUMN() -2)) -> - | J16: =indirect("counting!L"& ((row()-3)*8 + COLUMN() -2)) -> - | K16: =indirect("counting!L"& ((row()-3)*8 + COLUMN() -2)) -> - | L16: =sum(D16:K16) -> 0
B17: =category!B16 -> 7 | C17: =category!C16 -> システムモニタリング | D17: =indirect("counting!L"& ((row()-3)*8 + COLUMN() -2)) -> - | E17: =indirect("counting!L"& ((row()-3)*8 + COLUMN() -2)) -> - | F17: =indirect("counting!L"& ((row()-3)*8 + COLUMN() -2)) -> - | G17: =indirect("counting!L"& ((row()-3)*8 + COLUMN() -2)) -> - | H17: =indirect("counting!L"& ((row()-3)*8 + COLUMN() -2)) -> - | I17: =indirect("counting!L"& ((row()-3)*8 + COLUMN() -2)) -> - | J17: =indirect("counting!L"& ((row()-3)*8 + COLUMN() -2)) -> - | K17: =indirect("counting!L"& ((row()-3)*8 + COLUMN() -2)) -> - | L17: =sum(D17:K17) -> 0
B18: =category!B17 -> 8 | C18: =category!C17 -> セキュリティシフトレフト | D18: =indirect("counting!L"& ((row()-3)*8 + COLUMN() -2)) -> - | E18: =indirect("counting!L"& ((row()-3)*8 + COLUMN() -2)) -> - | F18: =indirect("counting!L"& ((row()-3)*8 + COLUMN() -2)) -> - | G18: =indirect("counting!L"& ((row()-3)*8 + COLUMN() -2)) -> - | H18: =indirect("counting!L"& ((row()-3)*8 + COLUMN() -2)) -> - | I18: =indirect("counting!L"& ((row()-3)*8 + COLUMN() -2)) -> - | J18: =indirect("counting!L"& ((row()-3)*8 + COLUMN() -2)) -> - | K18: =indirect("counting!L"& ((row()-3)*8 + COLUMN() -2)) -> - | L18: =sum(D18:K18) -> 0
A19: データ | B19: =category!B18 -> 1 | C19: =category!C18 -> 顧客接点のデジタル化 | D19: =indirect("counting!L"& ((row()-3)*8 + COLUMN() -2)) -> - | E19: =indirect("counting!L"& ((row()-3)*8 + COLUMN() -2)) -> - | F19: =indirect("counting!L"& ((row()-3)*8 + COLUMN() -2)) -> - | G19: =indirect("counting!L"& ((row()-3)*8 + COLUMN() -2)) -> - | H19: =indirect("counting!L"& ((row()-3)*8 + COLUMN() -2)) -> - | I19: =indirect("counting!L"& ((row()-3)*8 + COLUMN() -2)) -> - | J19: =indirect("counting!L"& ((row()-3)*8 + COLUMN() -2)) -> - | K19: =indirect("counting!L"& ((row()-3)*8 + COLUMN() -2)) -> - | L19: =sum(D19:K19) -> 0 | M19: =sum(L19:L26) -> 0 | N19: =((M19-stats!B4)/stats!C4)*10+50 -> 24.86535 | O19: =vlookup(N19,rating!$B$2:$D$13,3,TRUE) -> DD
B20: =category!B19 -> 2 | C20: =category!C19 -> 事業活動データの収集 | D20: =indirect("counting!L"& ((row()-3)*8 + COLUMN() -2)) -> - | E20: =indirect("counting!L"& ((row()-3)*8 + COLUMN() -2)) -> - | F20: =indirect("counting!L"& ((row()-3)*8 + COLUMN() -2)) -> - | G20: =indirect("counting!L"& ((row()-3)*8 + COLUMN() -2)) -> - | H20: =indirect("counting!L"& ((row()-3)*8 + COLUMN() -2)) -> - | I20: =indirect("counting!L"& ((row()-3)*8 + COLUMN() -2)) -> - | J20: =indirect("counting!L"& ((row()-3)*8 + COLUMN() -2)) -> - | K20: =indirect("counting!L"& ((row()-3)*8 + COLUMN() -2)) -> - | L20: =sum(D20:K20) -> 0
B21: =category!B20 -> 3 | C21: =category!C20 -> データ蓄積・分析基盤 | D21: =indirect("counting!L"& ((row()-3)*8 + COLUMN() -2)) -> - | E21: =indirect("counting!L"& ((row()-3)*8 + COLUMN() -2)) -> - | F21: =indirect("counting!L"& ((row()-3)*8 + COLUMN() -2)) -> - | G21: =indirect("counting!L"& ((row()-3)*8 + COLUMN() -2)) -> - | H21: =indirect("counting!L"& ((row()-3)*8 + COLUMN() -2)) -> - | I21: =indirect("counting!L"& ((row()-3)*8 + COLUMN() -2)) -> - | J21: =indirect("counting!L"& ((row()-3)*8 + COLUMN() -2)) -> - | K21: =indirect("counting!L"& ((row()-3)*8 + COLUMN() -2)) -> - | L21: =sum(D21:K21) -> 0
B22: =category!B21 -> 4 | C22: =category!C21 -> データ処理パイプライン | D22: =indirect("counting!L"& ((row()-3)*8 + COLUMN() -2)) -> - | E22: =indirect("counting!L"& ((row()-3)*8 + COLUMN() -2)) -> - | F22: =indirect("counting!L"& ((row()-3)*8 + COLUMN() -2)) -> - | G22: =indirect("counting!L"& ((row()-3)*8 + COLUMN() -2)) -> - | H22: =indirect("counting!L"& ((row()-3)*8 + COLUMN() -2)) -> - | I22: =indirect("counting!L"& ((row()-3)*8 + COLUMN() -2)) -> - | J22: =indirect("counting!L"& ((row()-3)*8 + COLUMN() -2)) -> - | K22: =indirect("counting!L"& ((row()-3)*8 + COLUMN() -2)) -> - | L22: =sum(D22:K22) -> 0
B23: =category!B22 -> 5 | C23: =category!C22 -> データ可視化とリテラシー | D23: =indirect("counting!L"& ((row()-3)*8 + COLUMN() -2)) -> - | E23: =indirect("counting!L"& ((row()-3)*8 + COLUMN() -2)) -> - | F23: =indirect("counting!L"& ((row()-3)*8 + COLUMN() -2)) -> - | G23: =indirect("counting!L"& ((row()-3)*8 + COLUMN() -2)) -> - | H23: =indirect("counting!L"& ((row()-3)*8 + COLUMN() -2)) -> - | I23: =indirect("counting!L"& ((row()-3)*8 + COLUMN() -2)) -> - | J23: =indirect("counting!L"& ((row()-3)*8 + COLUMN() -2)) -> - | K23: =indirect("counting!L"& ((row()-3)*8 + COLUMN() -2)) -> - | L23: =sum(D23:K23) -> 0
B24: =category!B23 -> 6 | C24: =category!C23 -> 機械学習プロジェクト管理 | D24: =indirect("counting!L"& ((row()-3)*8 + COLUMN() -2)) -> - | E24: =indirect("counting!L"& ((row()-3)*8 + COLUMN() -2)) -> - | F24: =indirect("counting!L"& ((row()-3)*8 + COLUMN() -2)) -> - | G24: =indirect("counting!L"& ((row()-3)*8 + COLUMN() -2)) -> - | H24: =indirect("counting!L"& ((row()-3)*8 + COLUMN() -2)) -> - | I24: =indirect("counting!L"& ((row()-3)*8 + COLUMN() -2)) -> - | J24: =indirect("counting!L"& ((row()-3)*8 + COLUMN() -2)) -> - | K24: =indirect("counting!L"& ((row()-3)*8 + COLUMN() -2)) -> - | L24: =sum(D24:K24) -> 0
B25: =category!B24 -> 7 | C25: =category!C24 -> マーケティング自動化 | D25: =indirect("counting!L"& ((row()-3)*8 + COLUMN() -2)) -> - | E25: =indirect("counting!L"& ((row()-3)*8 + COLUMN() -2)) -> - | F25: =indirect("counting!L"& ((row()-3)*8 + COLUMN() -2)) -> - | G25: =indirect("counting!L"& ((row()-3)*8 + COLUMN() -2)) -> - | H25: =indirect("counting!L"& ((row()-3)*8 + COLUMN() -2)) -> - | I25: =indirect("counting!L"& ((row()-3)*8 + COLUMN() -2)) -> - | J25: =indirect("counting!L"& ((row()-3)*8 + COLUMN() -2)) -> - | K25: =indirect("counting!L"& ((row()-3)*8 + COLUMN() -2)) -> - | L25: =sum(D25:K25) -> 0
B26: =category!B25 -> 8 | C26: =category!C25 -> 自動的な意思決定 | D26: =indirect("counting!L"& ((row()-3)*8 + COLUMN() -2)) -> - | E26: =indirect("counting!L"& ((row()-3)*8 + COLUMN() -2)) -> - | F26: =indirect("counting!L"& ((row()-3)*8 + COLUMN() -2)) -> - | G26: =indirect("counting!L"& ((row()-3)*8 + COLUMN() -2)) -> - | H26: =indirect("counting!L"& ((row()-3)*8 + COLUMN() -2)) -> - | I26: =indirect("counting!L"& ((row()-3)*8 + COLUMN() -2)) -> - | J26: =indirect("counting!L"& ((row()-3)*8 + COLUMN() -2)) -> - | K26: =indirect("counting!L"& ((row()-3)*8 + COLUMN() -2)) -> - | L26: =sum(D26:K26) -> 0
A27: デザイン | B27: =category!B26 -> 1 | C27: =category!C26 -> ペルソナの設定 | D27: =indirect("counting!L"& ((row()-3)*8 + COLUMN() -2)) -> - | E27: =indirect("counting!L"& ((row()-3)*8 + COLUMN() -2)) -> - | F27: =indirect("counting!L"& ((row()-3)*8 + COLUMN() -2)) -> - | G27: =indirect("counting!L"& ((row()-3)*8 + COLUMN() -2)) -> - | H27: =indirect("counting!L"& ((row()-3)*8 + COLUMN() -2)) -> - | I27: =indirect("counting!L"& ((row()-3)*8 + COLUMN() -2)) -> - | J27: =indirect("counting!L"& ((row()-3)*8 + COLUMN() -2)) -> - | K27: =indirect("counting!L"& ((row()-3)*8 + COLUMN() -2)) -> - | L27: =sum(D27:K27) -> 0 | M27: =sum(L27:L34) -> 0 | N27: =((M27-stats!B5)/stats!C5)*10+50 -> 21.414822 | O27: =vlookup(N27,rating!$B$2:$D$13,3,TRUE) -> DD
B28: =category!B27 -> 2 | C28: =category!C27 -> 顧客体験 | D28: =indirect("counting!L"& ((row()-3)*8 + COLUMN() -2)) -> - | E28: =indirect("counting!L"& ((row()-3)*8 + COLUMN() -2)) -> - | F28: =indirect("counting!L"& ((row()-3)*8 + COLUMN() -2)) -> - | G28: =indirect("counting!L"& ((row()-3)*8 + COLUMN() -2)) -> - | H28: =indirect("counting!L"& ((row()-3)*8 + COLUMN() -2)) -> - | I28: =indirect("counting!L"& ((row()-3)*8 + COLUMN() -2)) -> - | J28: =indirect("counting!L"& ((row()-3)*8 + COLUMN() -2)) -> - | K28: =indirect("counting!L"& ((row()-3)*8 + COLUMN() -2)) -> - | L28: =sum(D28:K28) -> 0
B29: =category!B28 -> 3 | C29: =category!C28 -> ユーザーインタビュー | D29: =indirect("counting!L"& ((row()-3)*8 + COLUMN() -2)) -> - | E29: =indirect("counting!L"& ((row()-3)*8 + COLUMN() -2)) -> - | F29: =indirect("counting!L"& ((row()-3)*8 + COLUMN() -2)) -> - | G29: =indirect("counting!L"& ((row()-3)*8 + COLUMN() -2)) -> - | H29: =indirect("counting!L"& ((row()-3)*8 + COLUMN() -2)) -> - | I29: =indirect("counting!L"& ((row()-3)*8 + COLUMN() -2)) -> - | J29: =indirect("counting!L"& ((row()-3)*8 + COLUMN() -2)) -> - | K29: =indirect("counting!L"& ((row()-3)*8 + COLUMN() -2)) -> - | L29: =sum(D29:K29) -> 0
B30: =category!B29 -> 4 | C30: =category!C29 -> デザインシステムの管理 | D30: =indirect("counting!L"& ((row()-3)*8 + COLUMN() -2)) -> - | E30: =indirect("counting!L"& ((row()-3)*8 + COLUMN() -2)) -> - | F30: =indirect("counting!L"& ((row()-3)*8 + COLUMN() -2)) -> - | G30: =indirect("counting!L"& ((row()-3)*8 + COLUMN() -2)) -> - | H30: =indirect("counting!L"& ((row()-3)*8 + COLUMN() -2)) -> - | I30: =indirect("counting!L"& ((row()-3)*8 + COLUMN() -2)) -> - | J30: =indirect("counting!L"& ((row()-3)*8 + COLUMN() -2)) -> - | K30: =indirect("counting!L"& ((row()-3)*8 + COLUMN() -2)) -> - | L30: =sum(D30:K30) -> 0
B31: =category!B30 -> 5 | C31: =category!C30 -> デザイン組織 | D31: =indirect("counting!L"& ((row()-3)*8 + COLUMN() -2)) -> - | E31: =indirect("counting!L"& ((row()-3)*8 + COLUMN() -2)) -> - | F31: =indirect("counting!L"& ((row()-3)*8 + COLUMN() -2)) -> - | G31: =indirect("counting!L"& ((row()-3)*8 + COLUMN() -2)) -> - | H31: =indirect("counting!L"& ((row()-3)*8 + COLUMN() -2)) -> - | I31: =indirect("counting!L"& ((row()-3)*8 + COLUMN() -2)) -> - | J31: =indirect("counting!L"& ((row()-3)*8 + COLUMN() -2)) -> - | K31: =indirect("counting!L"& ((row()-3)*8 + COLUMN() -2)) -> - | L31: =sum(D31:K31) -> 0
B32: =category!B31 -> 6 | C32: =category!C31 -> プロトタイピング | D32: =indirect("counting!L"& ((row()-3)*8 + COLUMN() -2)) -> - | E32: =indirect("counting!L"& ((row()-3)*8 + COLUMN() -2)) -> - | F32: =indirect("counting!L"& ((row()-3)*8 + COLUMN() -2)) -> - | G32: =indirect("counting!L"& ((row()-3)*8 + COLUMN() -2)) -> - | H32: =indirect("counting!L"& ((row()-3)*8 + COLUMN() -2)) -> - | I32: =indirect("counting!L"& ((row()-3)*8 + COLUMN() -2)) -> - | J32: =indirect("counting!L"& ((row()-3)*8 + COLUMN() -2)) -> - | K32: =indirect("counting!L"& ((row()-3)*8 + COLUMN() -2)) -> - | L32: =sum(D32:K32) -> 0
B33: =category!B32 -> 7 | C33: =category!C32 -> ユーザビリティテスト | D33: =indirect("counting!L"& ((row()-3)*8 + COLUMN() -2)) -> - | E33: =indirect("counting!L"& ((row()-3)*8 + COLUMN() -2)) -> - | F33: =indirect("counting!L"& ((row()-3)*8 + COLUMN() -2)) -> - | G33: =indirect("counting!L"& ((row()-3)*8 + COLUMN() -2)) -> - | H33: =indirect("counting!L"& ((row()-3)*8 + COLUMN() -2)) -> - | I33: =indirect("counting!L"& ((row()-3)*8 + COLUMN() -2)) -> - | J33: =indirect("counting!L"& ((row()-3)*8 + COLUMN() -2)) -> - | K33: =indirect("counting!L"& ((row()-3)*8 + COLUMN() -2)) -> - | L33: =sum(D33:K33) -> 0
B34: =category!B33 -> 8 | C34: =category!C33 -> プロダクトマネジメント | D34: =indirect("counting!L"& ((row()-3)*8 + COLUMN() -2)) -> - | E34: =indirect("counting!L"& ((row()-3)*8 + COLUMN() -2)) -> - | F34: =indirect("counting!L"& ((row()-3)*8 + COLUMN() -2)) -> - | G34: =indirect("counting!L"& ((row()-3)*8 + COLUMN() -2)) -> - | H34: =indirect("counting!L"& ((row()-3)*8 + COLUMN() -2)) -> - | I34: =indirect("counting!L"& ((row()-3)*8 + COLUMN() -2)) -> - | J34: =indirect("counting!L"& ((row()-3)*8 + COLUMN() -2)) -> - | K34: =indirect("counting!L"& ((row()-3)*8 + COLUMN() -2)) -> - | L34: =sum(D34:K34) -> 0
A35: コーポレート | B35: =category!B34 -> 1 | C35: =category!C34 -> スパン・オブ・コントロール | D35: =indirect("counting!L"& ((row()-3)*8 + COLUMN() -2)) -> - | E35: =indirect("counting!L"& ((row()-3)*8 + COLUMN() -2)) -> - | F35: =indirect("counting!L"& ((row()-3)*8 + COLUMN() -2)) -> - | G35: =indirect("counting!L"& ((row()-3)*8 + COLUMN() -2)) -> - | H35: =indirect("counting!L"& ((row()-3)*8 + COLUMN() -2)) -> - | I35: =indirect("counting!L"& ((row()-3)*8 + COLUMN() -2)) -> - | J35: =indirect("counting!L"& ((row()-3)*8 + COLUMN() -2)) -> - | K35: =indirect("counting!L"& ((row()-3)*8 + COLUMN() -2)) -> - | L35: =sum(D35:K35) -> 0 | M35: =sum(L35:L42) -> 0 | N35: =((M35-stats!B6)/stats!C6)*10+50 -> 5.2046784 | O35: =vlookup(N35,rating!$B$2:$D$13,3,TRUE) -> DD
B36: =category!B35 -> 2 | C36: =category!C35 -> 開発者環境投資 | D36: =indirect("counting!L"& ((row()-3)*8 + COLUMN() -2)) -> - | E36: =indirect("counting!L"& ((row()-3)*8 + COLUMN() -2)) -> - | F36: =indirect("counting!L"& ((row()-3)*8 + COLUMN() -2)) -> - | G36: =indirect("counting!L"& ((row()-3)*8 + COLUMN() -2)) -> - | H36: =indirect("counting!L"& ((row()-3)*8 + COLUMN() -2)) -> - | I36: =indirect("counting!L"& ((row()-3)*8 + COLUMN() -2)) -> - | J36: =indirect("counting!L"& ((row()-3)*8 + COLUMN() -2)) -> - | K36: =indirect("counting!L"& ((row()-3)*8 + COLUMN() -2)) -> - | L36: =sum(D36:K36) -> 0
B37: =category!B36 -> 3 | C37: =category!C36 -> コミュニケーションツール | D37: =indirect("counting!L"& ((row()-3)*8 + COLUMN() -2)) -> - | E37: =indirect("counting!L"& ((row()-3)*8 + COLUMN() -2)) -> - | F37: =indirect("counting!L"& ((row()-3)*8 + COLUMN() -2)) -> - | G37: =indirect("counting!L"& ((row()-3)*8 + COLUMN() -2)) -> - | H37: =indirect("counting!L"& ((row()-3)*8 + COLUMN() -2)) -> - | I37: =indirect("counting!L"& ((row()-3)*8 + COLUMN() -2)) -> - | J37: =indirect("counting!L"& ((row()-3)*8 + COLUMN() -2)) -> - | K37: =indirect("counting!L"& ((row()-3)*8 + COLUMN() -2)) -> - | L37: =sum(D37:K37) -> 0
B38: =category!B37 -> 4 | C38: =category!C37 -> 人事制度・育成戦略 | D38: =indirect("counting!L"& ((row()-3)*8 + COLUMN() -2)) -> - | E38: =indirect("counting!L"& ((row()-3)*8 + COLUMN() -2)) -> - | F38: =indirect("counting!L"& ((row()-3)*8 + COLUMN() -2)) -> - | G38: =indirect("counting!L"& ((row()-3)*8 + COLUMN() -2)) -> - | H38: =indirect("counting!L"& ((row()-3)*8 + COLUMN() -2)) -> - | I38: =indirect("counting!L"& ((row()-3)*8 + COLUMN() -2)) -> - | J38: =indirect("counting!L"& ((row()-3)*8 + COLUMN() -2)) -> - | K38: =indirect("counting!L"& ((row()-3)*8 + COLUMN() -2)) -> - | L38: =sum(D38:K38) -> 0
B39: =category!B38 -> 5 | C39: =category!C38 -> デジタル人材採用戦略 | D39: =indirect("counting!L"& ((row()-3)*8 + COLUMN() -2)) -> - | E39: =indirect("counting!L"& ((row()-3)*8 + COLUMN() -2)) -> - | F39: =indirect("counting!L"& ((row()-3)*8 + COLUMN() -2)) -> - | G39: =indirect("counting!L"& ((row()-3)*8 + COLUMN() -2)) -> - | H39: =indirect("counting!L"& ((row()-3)*8 + COLUMN() -2)) -> - | I39: =indirect("counting!L"& ((row()-3)*8 + COLUMN() -2)) -> - | J39: =indirect("counting!L"& ((row()-3)*8 + COLUMN() -2)) -> - | K39: =indirect("counting!L"& ((row()-3)*8 + COLUMN() -2)) -> - | L39: =sum(D39:K39) -> 0
B40: =category!B39 -> 6 | C40: =category!C39 -> モダンなITサービスの活用 | D40: =indirect("counting!L"& ((row()-3)*8 + COLUMN() -2)) -> - | E40: =indirect("counting!L"& ((row()-3)*8 + COLUMN() -2)) -> - | F40: =indirect("counting!L"& ((row()-3)*8 + COLUMN() -2)) -> - | G40: =indirect("counting!L"& ((row()-3)*8 + COLUMN() -2)) -> - | H40: =indirect("counting!L"& ((row()-3)*8 + COLUMN() -2)) -> - | I40: =indirect("counting!L"& ((row()-3)*8 + COLUMN() -2)) -> - | J40: =indirect("counting!L"& ((row()-3)*8 + COLUMN() -2)) -> - | K40: =indirect("counting!L"& ((row()-3)*8 + COLUMN() -2)) -> - | L40: =sum(D40:K40) -> 0
...

Sheet 過去アセスメント変換
A1: テーマ | B1: No | C1: カテゴリー | D1: メトリクスの計測 | E1: 学習と改善 | F1: プラクティスと習慣 | I1: アンチパターン | P1: Name | R1: yes | S1: no | T1: but
A2: チーム | B2: =category!B2 -> 1 | C2: =category!C2 -> チーム構成と権限委譲 | M2: 1 | N2: =FLOOR((M2-1)/8,1)+1 -> 1 | O2: =mod(M2-1,8)+1 -> 1 | P2: ='アセスメント'!B3 -> TEAM-1-1 | Q2: =indirect("R"&N2+ 1&"C"&3+O2,FALSE) | R2: =IFERROR(__xludf.DUMMYFUNCTION("REGEXMATCH($Q2,""Yes"")"),FALSE) -> FALSE | S2: =IFERROR(__xludf.DUMMYFUNCTION("REGEXMATCH($Q2,""No"")"),FALSE) -> FALSE | T2: =IFERROR(__xludf.DUMMYFUNCTION("REGEXMATCH($Q2,""but"")"),FALSE) -> FALSE
B3: =category!B3 -> 2 | C3: =category!C3 -> チームビルディング | M3: 2 | N3: =FLOOR((M3-1)/8,1)+1 -> 1 | O3: =mod(M3-1,8)+1 -> 2 | P3: ='アセスメント'!B4 -> TEAM-1-2 | Q3: =indirect("R"&N3+ 1&"C"&3+O3,FALSE) | R3: =IFERROR(__xludf.DUMMYFUNCTION("REGEXMATCH($Q3,""Yes"")"),FALSE) -> FALSE | S3: =IFERROR(__xludf.DUMMYFUNCTION("REGEXMATCH($Q3,""No"")"),FALSE) -> FALSE | T3: =IFERROR(__xludf.DUMMYFUNCTION("REGEXMATCH($Q3,""but"")"),FALSE) -> FALSE
B4: =category!B4 -> 3 | C4: =category!C4 -> 心理的安全性 | M4: 3 | N4: =FLOOR((M4-1)/8,1)+1 -> 1 | O4: =mod(M4-1,8)+1 -> 3 | P4: ='アセスメント'!B5 -> TEAM-1-3 | Q4: =indirect("R"&N4+ 1&"C"&3+O4,FALSE) | R4: =IFERROR(__xludf.DUMMYFUNCTION("REGEXMATCH($Q4,""Yes"")"),FALSE) -> FALSE | S4: =IFERROR(__xludf.DUMMYFUNCTION("REGEXMATCH($Q4,""No"")"),FALSE) -> FALSE | T4: =IFERROR(__xludf.DUMMYFUNCTION("REGEXMATCH($Q4,""but"")"),FALSE) -> FALSE
B5: =category!B5 -> 4 | C5: =category!C5 -> タスクマネジメント | M5: 4 | N5: =FLOOR((M5-1)/8,1)+1 -> 1 | O5: =mod(M5-1,8)+1 -> 4 | P5: ='アセスメント'!B6 -> TEAM-1-4 | Q5: =indirect("R"&N5+ 1&"C"&3+O5,FALSE) | R5: =IFERROR(__xludf.DUMMYFUNCTION("REGEXMATCH($Q5,""Yes"")"),FALSE) -> FALSE | S5: =IFERROR(__xludf.DUMMYFUNCTION("REGEXMATCH($Q5,""No"")"),FALSE) -> FALSE | T5: =IFERROR(__xludf.DUMMYFUNCTION("REGEXMATCH($Q5,""but"")"),FALSE) -> FALSE
B6: =category!B6 -> 5 | C6: =category!C6 -> 透明性ある目標管理 | M6: 5 | N6: =FLOOR((M6-1)/8,1)+1 -> 1 | O6: =mod(M6-1,8)+1 -> 5 | P6: ='アセスメント'!B7 -> TEAM-1-5 | Q6: =indirect("R"&N6+ 1&"C"&3+O6,FALSE) | R6: =IFERROR(__xludf.DUMMYFUNCTION("REGEXMATCH($Q6,""Yes"")"),FALSE) -> FALSE | S6: =IFERROR(__xludf.DUMMYFUNCTION("REGEXMATCH($Q6,""No"")"),FALSE) -> FALSE | T6: =IFERROR(__xludf.DUMMYFUNCTION("REGEXMATCH($Q6,""but"")"),FALSE) -> FALSE
B7: =category!B7 -> 6 | C7: =category!C7 -> 経験主義的な見積りと計画 | M7: 6 | N7: =FLOOR((M7-1)/8,1)+1 -> 1 | O7: =mod(M7-1,8)+1 -> 6 | P7: ='アセスメント'!B8 -> TEAM-1-6 | Q7: =indirect("R"&N7+ 1&"C"&3+O7,FALSE) | R7: =IFERROR(__xludf.DUMMYFUNCTION("REGEXMATCH($Q7,""Yes"")"),FALSE) -> FALSE | S7: =IFERROR(__xludf.DUMMYFUNCTION("REGEXMATCH($Q7,""No"")"),FALSE) -> FALSE | T7: =IFERROR(__xludf.DUMMYFUNCTION("REGEXMATCH($Q7,""but"")"),FALSE) -> FALSE
B8: =category!B8 -> 7 | C8: =category!C8 -> ふりかえり習慣 | M8: 7 | N8: =FLOOR((M8-1)/8,1)+1 -> 1 | O8: =mod(M8-1,8)+1 -> 7 | P8: ='アセスメント'!B9 -> TEAM-1-7 | Q8: =indirect("R"&N8+ 1&"C"&3+O8,FALSE) | R8: =IFERROR(__xludf.DUMMYFUNCTION("REGEXMATCH($Q8,""Yes"")"),FALSE) -> FALSE | S8: =IFERROR(__xludf.DUMMYFUNCTION("REGEXMATCH($Q8,""No"")"),FALSE) -> FALSE | T8: =IFERROR(__xludf.DUMMYFUNCTION("REGEXMATCH($Q8,""but"")"),FALSE) -> FALSE
B9: =category!B9 -> 8 | C9: =category!C9 -> バリューストリーム最適化 | M9: 8 | N9: =FLOOR((M9-1)/8,1)+1 -> 1 | O9: =mod(M9-1,8)+1 -> 8 | P9: ='アセスメント'!B10 -> TEAM-1-8 | Q9: =indirect("R"&N9+ 1&"C"&3+O9,FALSE) | R9: =IFERROR(__xludf.DUMMYFUNCTION("REGEXMATCH($Q9,""Yes"")"),FALSE) -> FALSE | S9: =IFERROR(__xludf.DUMMYFUNCTION("REGEXMATCH($Q9,""No"")"),FALSE) -> FALSE | T9: =IFERROR(__xludf.DUMMYFUNCTION("REGEXMATCH($Q9,""but"")"),FALSE) -> FALSE
A10: システム | B10: =category!B10 -> 1 | C10: =category!C10 -> バージョン管理 | M10: 9 | N10: =FLOOR((M10-1)/8,1)+1 -> 2 | O10: =mod(M10-1,8)+1 -> 1 | P10: ='アセスメント'!B11 -> TEAM-2-1 | Q10: =indirect("R"&N10+ 1&"C"&3+O10,FALSE) | R10: =IFERROR(__xludf.DUMMYFUNCTION("REGEXMATCH($Q10,""Yes"")"),FALSE) -> FALSE | S10: =IFERROR(__xludf.DUMMYFUNCTION("REGEXMATCH($Q10,""No"")"),FALSE) -> FALSE | T10: =IFERROR(__xludf.DUMMYFUNCTION("REGEXMATCH($Q10,""but"")"),FALSE) -> FALSE
B11: =category!B11 -> 2 | C11: =category!C11 -> ソースコードの明確さ | M11: 10 | N11: =FLOOR((M11-1)/8,1)+1 -> 2 | O11: =mod(M11-1,8)+1 -> 2 | P11: ='アセスメント'!B12 -> TEAM-2-2 | Q11: =indirect("R"&N11+ 1&"C"&3+O11,FALSE) | R11: =IFERROR(__xludf.DUMMYFUNCTION("REGEXMATCH($Q11,""Yes"")"),FALSE) -> FALSE | S11: =IFERROR(__xludf.DUMMYFUNCTION("REGEXMATCH($Q11,""No"")"),FALSE) -> FALSE | T11: =IFERROR(__xludf.DUMMYFUNCTION("REGEXMATCH($Q11,""but"")"),FALSE) -> FALSE
B12: =category!B12 -> 3 | C12: =category!C12 -> 継続的インテグレーション | M12: 11 | N12: =FLOOR((M12-1)/8,1)+1 -> 2 | O12: =mod(M12-1,8)+1 -> 3 | P12: ='アセスメント'!B13 -> TEAM-2-3 | Q12: =indirect("R"&N12+ 1&"C"&3+O12,FALSE) | R12: =IFERROR(__xludf.DUMMYFUNCTION("REGEXMATCH($Q12,""Yes"")"),FALSE) -> FALSE | S12: =IFERROR(__xludf.DUMMYFUNCTION("REGEXMATCH($Q12,""No"")"),FALSE) -> FALSE | T12: =IFERROR(__xludf.DUMMYFUNCTION("REGEXMATCH($Q12,""but"")"),FALSE) -> FALSE
B13: =category!B13 -> 4 | C13: =category!C13 -> 継続的デプロイ | M13: 12 | N13: =FLOOR((M13-1)/8,1)+1 -> 2 | O13: =mod(M13-1,8)+1 -> 4 | P13: ='アセスメント'!B14 -> TEAM-2-4 | Q13: =indirect("R"&N13+ 1&"C"&3+O13,FALSE) | R13: =IFERROR(__xludf.DUMMYFUNCTION("REGEXMATCH($Q13,""Yes"")"),FALSE) -> FALSE | S13: =IFERROR(__xludf.DUMMYFUNCTION("REGEXMATCH($Q13,""No"")"),FALSE) -> FALSE | T13: =IFERROR(__xludf.DUMMYFUNCTION("REGEXMATCH($Q13,""but"")"),FALSE) -> FALSE
B14: =category!B14 -> 5 | C14: =category!C14 -> API駆動開発 | M14: 13 | N14: =FLOOR((M14-1)/8,1)+1 -> 2 | O14: =mod(M14-1,8)+1 -> 5 | P14: ='アセスメント'!B15 -> TEAM-2-5 | Q14: =indirect("R"&N14+ 1&"C"&3+O14,FALSE) | R14: =IFERROR(__xludf.DUMMYFUNCTION("REGEXMATCH($Q14,""Yes"")"),FALSE) -> FALSE | S14: =IFERROR(__xludf.DUMMYFUNCTION("REGEXMATCH($Q14,""No"")"),FALSE) -> FALSE | T14: =IFERROR(__xludf.DUMMYFUNCTION("REGEXMATCH($Q14,""but"")"),FALSE) -> FALSE
B15: =category!B15 -> 6 | C15: =category!C15 -> 疎結合アーキテクチャ | M15: 14 | N15: =FLOOR((M15-1)/8,1)+1 -> 2 | O15: =mod(M15-1,8)+1 -> 6 | P15: ='アセスメント'!B16 -> TEAM-2-6 | Q15: =indirect("R"&N15+ 1&"C"&3+O15,FALSE) | R15: =IFERROR(__xludf.DUMMYFUNCTION("REGEXMATCH($Q15,""Yes"")"),FALSE) -> FALSE | S15: =IFERROR(__xludf.DUMMYFUNCTION("REGEXMATCH($Q15,""No"")"),FALSE) -> FALSE | T15: =IFERROR(__xludf.DUMMYFUNCTION("REGEXMATCH($Q15,""but"")"),FALSE) -> FALSE
B16: =category!B16 -> 7 | C16: =category!C16 -> システムモニタリング | M16: 15 | N16: =FLOOR((M16-1)/8,1)+1 -> 2 | O16: =mod(M16-1,8)+1 -> 7 | P16: ='アセスメント'!B17 -> TEAM-2-7 | Q16: =indirect("R"&N16+ 1&"C"&3+O16,FALSE) | R16: =IFERROR(__xludf.DUMMYFUNCTION("REGEXMATCH($Q16,""Yes"")"),FALSE) -> FALSE | S16: =IFERROR(__xludf.DUMMYFUNCTION("REGEXMATCH($Q16,""No"")"),FALSE) -> FALSE | T16: =IFERROR(__xludf.DUMMYFUNCTION("REGEXMATCH($Q16,""but"")"),FALSE) -> FALSE
B17: =category!B17 -> 8 | C17: =category!C17 -> セキュリティシフトレフト | M17: 16 | N17: =FLOOR((M17-1)/8,1)+1 -> 2 | O17: =mod(M17-1,8)+1 -> 8 | P17: ='アセスメント'!B18 -> TEAM-2-8 | Q17: =indirect("R"&N17+ 1&"C"&3+O17,FALSE) | R17: =IFERROR(__xludf.DUMMYFUNCTION("REGEXMATCH($Q17,""Yes"")"),FALSE) -> FALSE | S17: =IFERROR(__xludf.DUMMYFUNCTION("REGEXMATCH($Q17,""No"")"),FALSE) -> FALSE | T17: =IFERROR(__xludf.DUMMYFUNCTION("REGEXMATCH($Q17,""but"")"),FALSE) -> FALSE
A18: データ | B18: =category!B18 -> 1 | C18: =category!C18 -> 顧客接点のデジタル化 | M18: 17 | N18: =FLOOR((M18-1)/8,1)+1 -> 3 | O18: =mod(M18-1,8)+1 -> 1 | P18: ='アセスメント'!B19 -> TEAM-3-1 | Q18: =indirect("R"&N18+ 1&"C"&3+O18,FALSE) | R18: =IFERROR(__xludf.DUMMYFUNCTION("REGEXMATCH($Q18,""Yes"")"),FALSE) -> FALSE | S18: =IFERROR(__xludf.DUMMYFUNCTION("REGEXMATCH($Q18,""No"")"),FALSE) -> FALSE | T18: =IFERROR(__xludf.DUMMYFUNCTION("REGEXMATCH($Q18,""but"")"),FALSE) -> FALSE
B19: =category!B19 -> 2 | C19: =category!C19 -> 事業活動データの収集 | M19: 18 | N19: =FLOOR((M19-1)/8,1)+1 -> 3 | O19: =mod(M19-1,8)+1 -> 2 | P19: ='アセスメント'!B20 -> TEAM-3-2 | Q19: =indirect("R"&N19+ 1&"C"&3+O19,FALSE) | R19: =IFERROR(__xludf.DUMMYFUNCTION("REGEXMATCH($Q19,""Yes"")"),FALSE) -> FALSE | S19: =IFERROR(__xludf.DUMMYFUNCTION("REGEXMATCH($Q19,""No"")"),FALSE) -> FALSE | T19: =IFERROR(__xludf.DUMMYFUNCTION("REGEXMATCH($Q19,""but"")"),FALSE) -> FALSE
B20: =category!B20 -> 3 | C20: =category!C20 -> データ蓄積・分析基盤 | M20: 19 | N20: =FLOOR((M20-1)/8,1)+1 -> 3 | O20: =mod(M20-1,8)+1 -> 3 | P20: ='アセスメント'!B21 -> TEAM-3-3 | Q20: =indirect("R"&N20+ 1&"C"&3+O20,FALSE) | R20: =IFERROR(__xludf.DUMMYFUNCTION("REGEXMATCH($Q20,""Yes"")"),FALSE) -> FALSE | S20: =IFERROR(__xludf.DUMMYFUNCTION("REGEXMATCH($Q20,""No"")"),FALSE) -> FALSE | T20: =IFERROR(__xludf.DUMMYFUNCTION("REGEXMATCH($Q20,""but"")"),FALSE) -> FALSE
B21: =category!B21 -> 4 | C21: =category!C21 -> データ処理パイプライン | M21: 20 | N21: =FLOOR((M21-1)/8,1)+1 -> 3 | O21: =mod(M21-1,8)+1 -> 4 | P21: ='アセスメント'!B22 -> TEAM-3-4 | Q21: =indirect("R"&N21+ 1&"C"&3+O21,FALSE) | R21: =IFERROR(__xludf.DUMMYFUNCTION("REGEXMATCH($Q21,""Yes"")"),FALSE) -> FALSE | S21: =IFERROR(__xludf.DUMMYFUNCTION("REGEXMATCH($Q21,""No"")"),FALSE) -> FALSE | T21: =IFERROR(__xludf.DUMMYFUNCTION("REGEXMATCH($Q21,""but"")"),FALSE) -> FALSE
B22: =category!B22 -> 5 | C22: =category!C22 -> データ可視化とリテラシー | M22: 21 | N22: =FLOOR((M22-1)/8,1)+1 -> 3 | O22: =mod(M22-1,8)+1 -> 5 | P22: ='アセスメント'!B23 -> TEAM-3-5 | Q22: =indirect("R"&N22+ 1&"C"&3+O22,FALSE) | R22: =IFERROR(__xludf.DUMMYFUNCTION("REGEXMATCH($Q22,""Yes"")"),FALSE) -> FALSE | S22: =IFERROR(__xludf.DUMMYFUNCTION("REGEXMATCH($Q22,""No"")"),FALSE) -> FALSE | T22: =IFERROR(__xludf.DUMMYFUNCTION("REGEXMATCH($Q22,""but"")"),FALSE) -> FALSE
B23: =category!B23 -> 6 | C23: =category!C23 -> 機械学習プロジェクト管理 | M23: 22 | N23: =FLOOR((M23-1)/8,1)+1 -> 3 | O23: =mod(M23-1,8)+1 -> 6 | P23: ='アセスメント'!B24 -> TEAM-3-6 | Q23: =indirect("R"&N23+ 1&"C"&3+O23,FALSE) | R23: =IFERROR(__xludf.DUMMYFUNCTION("REGEXMATCH($Q23,""Yes"")"),FALSE) -> FALSE | S23: =IFERROR(__xludf.DUMMYFUNCTION("REGEXMATCH($Q23,""No"")"),FALSE) -> FALSE | T23: =IFERROR(__xludf.DUMMYFUNCTION("REGEXMATCH($Q23,""but"")"),FALSE) -> FALSE
B24: =category!B24 -> 7 | C24: =category!C24 -> マーケティング自動化 | M24: 23 | N24: =FLOOR((M24-1)/8,1)+1 -> 3 | O24: =mod(M24-1,8)+1 -> 7 | P24: ='アセスメント'!B25 -> TEAM-3-7 | Q24: =indirect("R"&N24+ 1&"C"&3+O24,FALSE) | R24: =IFERROR(__xludf.DUMMYFUNCTION("REGEXMATCH($Q24,""Yes"")"),FALSE) -> FALSE | S24: =IFERROR(__xludf.DUMMYFUNCTION("REGEXMATCH($Q24,""No"")"),FALSE) -> FALSE | T24: =IFERROR(__xludf.DUMMYFUNCTION("REGEXMATCH($Q24,""but"")"),FALSE) -> FALSE
B25: =category!B25 -> 8 | C25: =category!C25 -> 自動的な意思決定 | M25: 24 | N25: =FLOOR((M25-1)/8,1)+1 -> 3 | O25: =mod(M25-1,8)+1 -> 8 | P25: ='アセスメント'!B26 -> TEAM-3-8 | Q25: =indirect("R"&N25+ 1&"C"&3+O25,FALSE) | R25: =IFERROR(__xludf.DUMMYFUNCTION("REGEXMATCH($Q25,""Yes"")"),FALSE) -> FALSE | S25: =IFERROR(__xludf.DUMMYFUNCTION("REGEXMATCH($Q25,""No"")"),FALSE) -> FALSE | T25: =IFERROR(__xludf.DUMMYFUNCTION("REGEXMATCH($Q25,""but"")"),FALSE) -> FALSE
A26: デザイン | B26: =category!B26 -> 1 | C26: =category!C26 -> ペルソナの設定 | M26: 25 | N26: =FLOOR((M26-1)/8,1)+1 -> 4 | O26: =mod(M26-1,8)+1 -> 1 | P26: ='アセスメント'!B27 -> TEAM-4-1 | Q26: =indirect("R"&N26+ 1&"C"&3+O26,FALSE) | R26: =IFERROR(__xludf.DUMMYFUNCTION("REGEXMATCH($Q26,""Yes"")"),FALSE) -> FALSE | S26: =IFERROR(__xludf.DUMMYFUNCTION("REGEXMATCH($Q26,""No"")"),FALSE) -> FALSE | T26: =IFERROR(__xludf.DUMMYFUNCTION("REGEXMATCH($Q26,""but"")"),FALSE) -> FALSE
B27: =category!B27 -> 2 | C27: =category!C27 -> 顧客体験 | M27: 26 | N27: =FLOOR((M27-1)/8,1)+1 -> 4 | O27: =mod(M27-1,8)+1 -> 2 | P27: ='アセスメント'!B28 -> TEAM-4-2 | Q27: =indirect("R"&N27+ 1&"C"&3+O27,FALSE) | R27: =IFERROR(__xludf.DUMMYFUNCTION("REGEXMATCH($Q27,""Yes"")"),FALSE) -> FALSE | S27: =IFERROR(__xludf.DUMMYFUNCTION("REGEXMATCH($Q27,""No"")"),FALSE) -> FALSE | T27: =IFERROR(__xludf.DUMMYFUNCTION("REGEXMATCH($Q27,""but"")"),FALSE) -> FALSE
B28: =category!B28 -> 3 | C28: =category!C28 -> ユーザーインタビュー | M28: 27 | N28: =FLOOR((M28-1)/8,1)+1 -> 4 | O28: =mod(M28-1,8)+1 -> 3 | P28: ='アセスメント'!B29 -> TEAM-4-3 | Q28: =indirect("R"&N28+ 1&"C"&3+O28,FALSE) | R28: =IFERROR(__xludf.DUMMYFUNCTION("REGEXMATCH($Q28,""Yes"")"),FALSE) -> FALSE | S28: =IFERROR(__xludf.DUMMYFUNCTION("REGEXMATCH($Q28,""No"")"),FALSE) -> FALSE | T28: =IFERROR(__xludf.DUMMYFUNCTION("REGEXMATCH($Q28,""but"")"),FALSE) -> FALSE
B29: =category!B29 -> 4 | C29: =category!C29 -> デザインシステムの管理 | M29: 28 | N29: =FLOOR((M29-1)/8,1)+1 -> 4 | O29: =mod(M29-1,8)+1 -> 4 | P29: ='アセスメント'!B30 -> TEAM-4-4 | Q29: =indirect("R"&N29+ 1&"C"&3+O29,FALSE) | R29: =IFERROR(__xludf.DUMMYFUNCTION("REGEXMATCH($Q29,""Yes"")"),FALSE) -> FALSE | S29: =IFERROR(__xludf.DUMMYFUNCTION("REGEXMATCH($Q29,""No"")"),FALSE) -> FALSE | T29: =IFERROR(__xludf.DUMMYFUNCTION("REGEXMATCH($Q29,""but"")"),FALSE) -> FALSE
B30: =category!B30 -> 5 | C30: =category!C30 -> デザイン組織 | M30: 29 | N30: =FLOOR((M30-1)/8,1)+1 -> 4 | O30: =mod(M30-1,8)+1 -> 5 | P30: ='アセスメント'!B31 -> TEAM-4-5 | Q30: =indirect("R"&N30+ 1&"C"&3+O30,FALSE) | R30: =IFERROR(__xludf.DUMMYFUNCTION("REGEXMATCH($Q30,""Yes"")"),FALSE) -> FALSE | S30: =IFERROR(__xludf.DUMMYFUNCTION("REGEXMATCH($Q30,""No"")"),FALSE) -> FALSE | T30: =IFERROR(__xludf.DUMMYFUNCTION("REGEXMATCH($Q30,""but"")"),FALSE) -> FALSE
B31: =category!B31 -> 6 | C31: =category!C31 -> プロトタイピング | M31: 30 | N31: =FLOOR((M31-1)/8,1)+1 -> 4 | O31: =mod(M31-1,8)+1 -> 6 | P31: ='アセスメント'!B32 -> TEAM-4-6 | Q31: =indirect("R"&N31+ 1&"C"&3+O31,FALSE) | R31: =IFERROR(__xludf.DUMMYFUNCTION("REGEXMATCH($Q31,""Yes"")"),FALSE) -> FALSE | S31: =IFERROR(__xludf.DUMMYFUNCTION("REGEXMATCH($Q31,""No"")"),FALSE) -> FALSE | T31: =IFERROR(__xludf.DUMMYFUNCTION("REGEXMATCH($Q31,""but"")"),FALSE) -> FALSE
B32: =category!B32 -> 7 | C32: =category!C32 -> ユーザビリティテスト | M32: 31 | N32: =FLOOR((M32-1)/8,1)+1 -> 4 | O32: =mod(M32-1,8)+1 -> 7 | P32: ='アセスメント'!B33 -> TEAM-4-7 | Q32: =indirect("R"&N32+ 1&"C"&3+O32,FALSE) | R32: =IFERROR(__xludf.DUMMYFUNCTION("REGEXMATCH($Q32,""Yes"")"),FALSE) -> FALSE | S32: =IFERROR(__xludf.DUMMYFUNCTION("REGEXMATCH($Q32,""No"")"),FALSE) -> FALSE | T32: =IFERROR(__xludf.DUMMYFUNCTION("REGEXMATCH($Q32,""but"")"),FALSE) -> FALSE
B33: =category!B33 -> 8 | C33: =category!C33 -> プロダクトマネジメント | M33: 32 | N33: =FLOOR((M33-1)/8,1)+1 -> 4 | O33: =mod(M33-1,8)+1 -> 8 | P33: ='アセスメント'!B34 -> TEAM-4-8 | Q33: =indirect("R"&N33+ 1&"C"&3+O33,FALSE) | R33: =IFERROR(__xludf.DUMMYFUNCTION("REGEXMATCH($Q33,""Yes"")"),FALSE) -> FALSE | S33: =IFERROR(__xludf.DUMMYFUNCTION("REGEXMATCH($Q33,""No"")"),FALSE) -> FALSE | T33: =IFERROR(__xludf.DUMMYFUNCTION("REGEXMATCH($Q33,""but"")"),FALSE) -> FALSE
A34: コーポレート | B34: =category!B34 -> 1 | C34: =category!C34 -> スパン・オブ・コントロール | M34: 33 | N34: =FLOOR((M34-1)/8,1)+1 -> 5 | O34: =mod(M34-1,8)+1 -> 1 | P34: ='アセスメント'!B35 -> TEAM-5-1 | Q34: =indirect("R"&N34+ 1&"C"&3+O34,FALSE) | R34: =IFERROR(__xludf.DUMMYFUNCTION("REGEXMATCH($Q34,""Yes"")"),FALSE) -> FALSE | S34: =IFERROR(__xludf.DUMMYFUNCTION("REGEXMATCH($Q34,""No"")"),FALSE) -> FALSE | T34: =IFERROR(__xludf.DUMMYFUNCTION("REGEXMATCH($Q34,""but"")"),FALSE) -> FALSE
B35: =category!B35 -> 2 | C35: =category!C35 -> 開発者環境投資 | M35: 34 | N35: =FLOOR((M35-1)/8,1)+1 -> 5 | O35: =mod(M35-1,8)+1 -> 2 | P35: ='アセスメント'!B36 -> TEAM-5-2 | Q35: =indirect("R"&N35+ 1&"C"&3+O35,FALSE) | R35: =IFERROR(__xludf.DUMMYFUNCTION("REGEXMATCH($Q35,""Yes"")"),FALSE) -> FALSE | S35: =IFERROR(__xludf.DUMMYFUNCTION("REGEXMATCH($Q35,""No"")"),FALSE) -> FALSE | T35: =IFERROR(__xludf.DUMMYFUNCTION("REGEXMATCH($Q35,""but"")"),FALSE) -> FALSE
B36: =category!B36 -> 3 | C36: =category!C36 -> コミュニケーションツール | M36: 35 | N36: =FLOOR((M36-1)/8,1)+1 -> 5 | O36: =mod(M36-1,8)+1 -> 3 | P36: ='アセスメント'!B37 -> TEAM-5-3 | Q36: =indirect("R"&N36+ 1&"C"&3+O36,FALSE) | R36: =IFERROR(__xludf.DUMMYFUNCTION("REGEXMATCH($Q36,""Yes"")"),FALSE) -> FALSE | S36: =IFERROR(__xludf.DUMMYFUNCTION("REGEXMATCH($Q36,""No"")"),FALSE) -> FALSE | T36: =IFERROR(__xludf.DUMMYFUNCTION("REGEXMATCH($Q36,""but"")"),FALSE) -> FALSE
B37: =category!B37 -> 4 | C37: =category!C37 -> 人事制度・育成戦略 | M37: 36 | N37: =FLOOR((M37-1)/8,1)+1 -> 5 | O37: =mod(M37-1,8)+1 -> 4 | P37: ='アセスメント'!B38 -> TEAM-5-4 | Q37: =indirect("R"&N37+ 1&"C"&3+O37,FALSE) | R37: =IFERROR(__xludf.DUMMYFUNCTION("REGEXMATCH($Q37,""Yes"")"),FALSE) -> FALSE | S37: =IFERROR(__xludf.DUMMYFUNCTION("REGEXMATCH($Q37,""No"")"),FALSE) -> FALSE | T37: =IFERROR(__xludf.DUMMYFUNCTION("REGEXMATCH($Q37,""but"")"),FALSE) -> FALSE
B38: =category!B38 -> 5 | C38: =category!C38 -> デジタル人材採用戦略 | M38: 37 | N38: =FLOOR((M38-1)/8,1)+1 -> 5 | O38: =mod(M38-1,8)+1 -> 5 | P38: ='アセスメント'!B39 -> TEAM-5-5 | Q38: =indirect("R"&N38+ 1&"C"&3+O38,FALSE) | R38: =IFERROR(__xludf.DUMMYFUNCTION("REGEXMATCH($Q38,""Yes"")"),FALSE) -> FALSE | S38: =IFERROR(__xludf.DUMMYFUNCTION("REGEXMATCH($Q38,""No"")"),FALSE) -> FALSE | T38: =IFERROR(__xludf.DUMMYFUNCTION("REGEXMATCH($Q38,""but"")"),FALSE) -> FALSE
B39: =category!B39 -> 6 | C39: =category!C39 -> モダンなITサービスの活用 | M39: 38 | N39: =FLOOR((M39-1)/8,1)+1 -> 5 | O39: =mod(M39-1,8)+1 -> 6 | P39: ='アセスメント'!B40 -> TEAM-5-6 | Q39: =indirect("R"&N39+ 1&"C"&3+O39,FALSE) | R39: =IFERROR(__xludf.DUMMYFUNCTION("REGEXMATCH($Q39,""Yes"")"),FALSE) -> FALSE | S39: =IFERROR(__xludf.DUMMYFUNCTION("REGEXMATCH($Q39,""No"")"),FALSE) -> FALSE | T39: =IFERROR(__xludf.DUMMYFUNCTION("REGEXMATCH($Q39,""but"")"),FALSE) -> FALSE
B40: =category!B40 -> 7 | C40: =category!C40 -> 経営のデジタルファースト | M40: 39 | N40: =FLOOR((M40-1)/8,1)+1 -> 5 | O40: =mod(M40-1,8)+1 -> 7 | P40: ='アセスメント'!B41 -> TEAM-5-7 | Q40: =indirect("R"&N40+ 1&"C"&3+O40,FALSE) | R40: =IFERROR(__xludf.DUMMYFUNCTION("REGEXMATCH($Q40,""Yes"")"),FALSE) -> FALSE | S40: =IFERROR(__xludf.DUMMYFUNCTION("REGEXMATCH($Q40,""No"")"),FALSE) -> FALSE | T40: =IFERROR(__xludf.DUMMYFUNCTION("REGEXMATCH($Q40,""but"")"),FALSE) -> FALSE
...

Sheet progressbar
B5: 記入済み | C5: =countif(counting!I2:I321,TRUE) -> 0
B6: ブロック数 | C6: 20
B7: 総数 | C7: 320
B8: 単位 | C8: =C7/C6 -> 16
E9: ="progress :"&textjoin("",TRUE,D10:D29)&" "&C5 & "/" &C7 -> progress :□□□□□□□□□□□□□□□□□□□□ 0/320
B10: 1 | C10: =B10*$C$8 -> 16 | D10: =if($C$5>=C10,"■","□") -> □
B11: 2 | C11: =B11*$C$8 -> 32 | D11: =if($C$5>=C11,"■","□") -> □ | E11: チーム | F11: 3 | G11: =E$17&F11 -> #gid=0&range=F3
B12: 3 | C12: =B12*$C$8 -> 48 | D12: =if($C$5>=C12,"■","□") -> □ | E12: システム | F12: =64+F11 -> 67 | G12: =E$17&F12 -> #gid=0&range=F67
B13: 4 | C13: =B13*$C$8 -> 64 | D13: =if($C$5>=C13,"■","□") -> □ | E13: データ駆動 | F13: =64+F12 -> 131 | G13: =E$17&F13 -> #gid=0&range=F131
B14: 5 | C14: =B14*$C$8 -> 80 | D14: =if($C$5>=C14,"■","□") -> □ | E14: デザイン思考 | F14: =64+F13 -> 195 | G14: =E$17&F14 -> #gid=0&range=F195
B15: 6 | C15: =B15*$C$8 -> 96 | D15: =if($C$5>=C15,"■","□") -> □ | E15: コーポレート | F15: =64+F14 -> 259 | G15: =E$17&F15 -> #gid=0&range=F259
B16: 7 | C16: =B16*$C$8 -> 112 | D16: =if($C$5>=C16,"■","□") -> □
B17: 8 | C17: =B17*$C$8 -> 128 | D17: =if($C$5>=C17,"■","□") -> □ | E17: #gid=0&range=F
B18: 9 | C18: =B18*$C$8 -> 144 | D18: =if($C$5>=C18,"■","□") -> □
B19: 10 | C19: =B19*$C$8 -> 160 | D19: =if($C$5>=C19,"■","□") -> □
B20: 11 | C20: =B20*$C$8 -> 176 | D20: =if($C$5>=C20,"■","□") -> □ | E20: =MATCH(FALSE,counting!I2:I330,0)+2 -> 3
B21: 12 | C21: =B21*$C$8 -> 192 | D21: =if($C$5>=C21,"■","□") -> □ | E21: =E17&E20 -> #gid=0&range=F3
B22: 13 | C22: =B22*$C$8 -> 208 | D22: =if($C$5>=C22,"■","□") -> □
B23: 14 | C23: =B23*$C$8 -> 224 | D23: =if($C$5>=C23,"■","□") -> □
B24: 15 | C24: =B24*$C$8 -> 240 | D24: =if($C$5>=C24,"■","□") -> □
B25: 16 | C25: =B25*$C$8 -> 256 | D25: =if($C$5>=C25,"■","□") -> □
B26: 17 | C26: =B26*$C$8 -> 272 | D26: =if($C$5>=C26,"■","□") -> □
B27: 18 | C27: =B27*$C$8 -> 288 | D27: =if($C$5>=C27,"■","□") -> □
B28: 19 | C28: =B28*$C$8 -> 304 | D28: =if($C$5>=C28,"■","□") -> □
B29: 20 | C29: =B29*$C$8 -> 320 | D29: =if($C$5>=C29,"■","□") -> □

Sheet rating
B2: 偏差値下限 | C2: 偏差値上限 | D2: レイティング
B3: 0 | C3: 33 | D3: DD
B4: =C3 -> 33 | C4: 39 | D4: DDD
B5: =C4 -> 39 | C5: 42 | D5: C
B6: =C5 -> 42 | C6: 45 | D6: CC
B7: =C6 -> 45 | C7: 48 | D7: CCC
B8: =C7 -> 48 | C8: 52 | D8: B
B9: =C8 -> 52 | C9: 55 | D9: BB
B10: =C9 -> 55 | C10: 58 | D10: BBB
B11: =C10 -> 58 | C11: 61 | D11: A
B12: =C11 -> 61 | C12: 67 | D12: AA
B13: =C12 -> 67 | C13: 100 | D13: AAA
A17: 1 | B17: =vlookup(A17,rating!$B$2:$D$13,3,TRUE) -> DD
A18: 2 | B18: =vlookup(A18,rating!$B$2:$D$13,3,TRUE) -> DD
A19: 3 | B19: =vlookup(A19,rating!$B$2:$D$13,3,TRUE) -> DD
A20: 4 | B20: =vlookup(A20,rating!$B$2:$D$13,3,TRUE) -> DD
A21: 5 | B21: =vlookup(A21,rating!$B$2:$D$13,3,TRUE) -> DD
A22: 6 | B22: =vlookup(A22,rating!$B$2:$D$13,3,TRUE) -> DD
A23: 7 | B23: =vlookup(A23,rating!$B$2:$D$13,3,TRUE) -> DD
A24: 8 | B24: =vlookup(A24,rating!$B$2:$D$13,3,TRUE) -> DD
A25: 9 | B25: =vlookup(A25,rating!$B$2:$D$13,3,TRUE) -> DD
A26: 10 | B26: =vlookup(A26,rating!$B$2:$D$13,3,TRUE) -> DD
A27: 11 | B27: =vlookup(A27,rating!$B$2:$D$13,3,TRUE) -> DD
A28: 12 | B28: =vlookup(A28,rating!$B$2:$D$13,3,TRUE) -> DD
... A119: 103 | B119: =vlookup(A119,rating!$B$2:$D$13,3,TRUE) -> AAA

Sheet counting
C1: yes | D1: no | E1: but | F1: valid | G1: fill | H1: alert | I1: count | J1: isantipattern | L1: point
A2: ='アセスメント'!B3 -> TEAM-1-1 | B2: =criteria!D2 -> メトリクスの計測 | C2: ='アセスメント'!F3 -> FALSE | D2: ='アセスメント'!G3 -> FALSE | E2: ='アセスメント'!H3 -> FALSE | F2: =not(and(C2,D2)) -> TRUE | G2: =or(C2,D2) -> FALSE | H2: =and(G2,not(F2)) -> FALSE | I2: =and(G2,F2) -> FALSE | J2: =if(B2="アンチパターン",true,false) -> FALSE | K2: =if(E2,0.5,if(C2,1,0)) -> 0 | L2: =if(H2,"@" ,if(G2, if(J2,1-K2,K2),"-")) -> - | M2: =IFERROR(__xludf.DUMMYFUNCTION("split(A2,""-"")"),"TEAM") -> TEAM | N2: =IFERROR(__xludf.DUMMYFUNCTION("""COMPUTED_VALUE"""),1.0) -> 1 | O2: =IFERROR(__xludf.DUMMYFUNCTION("""COMPUTED_VALUE"""),1.0) -> 1
A3: ='アセスメント'!B4 -> TEAM-1-2 | B3: =criteria!D3 -> 学習と改善 | C3: ='アセスメント'!F4 -> FALSE | D3: ='アセスメント'!G4 -> FALSE | E3: ='アセスメント'!H4 -> FALSE | F3: =not(and(C3,D3)) -> TRUE | G3: =or(C3,D3) -> FALSE | H3: =and(G3,not(F3)) -> FALSE | I3: =and(G3,F3) -> FALSE | J3: =if(B3="アンチパターン",true,false) -> FALSE | K3: =if(E3,0.5,if(C3,1,0)) -> 0 | L3: =if(H3,"@" ,if(G3, if(J3,1-K3,K3),"-")) -> - | M3: =IFERROR(__xludf.DUMMYFUNCTION("split(A3,""-"")"),"TEAM") -> TEAM | N3: =IFERROR(__xludf.DUMMYFUNCTION("""COMPUTED_VALUE"""),1.0) -> 1 | O3: =IFERROR(__xludf.DUMMYFUNCTION("""COMPUTED_VALUE"""),2.0) -> 2
A4: ='アセスメント'!B5 -> TEAM-1-3 | B4: =criteria!D4 -> プラクティス | C4: ='アセスメント'!F5 -> FALSE | D4: ='アセスメント'!G5 -> FALSE | E4: ='アセスメント'!H5 -> FALSE | F4: =not(and(C4,D4)) -> TRUE | G4: =or(C4,D4) -> FALSE | H4: =and(G4,not(F4)) -> FALSE | I4: =and(G4,F4) -> FALSE | J4: =if(B4="アンチパターン",true,false) -> FALSE | K4: =if(E4,0.5,if(C4,1,0)) -> 0 | L4: =if(H4,"@" ,if(G4, if(J4,1-K4,K4),"-")) -> - | M4: =IFERROR(__xludf.DUMMYFUNCTION("split(A4,""-"")"),"TEAM") -> TEAM | N4: =IFERROR(__xludf.DUMMYFUNCTION("""COMPUTED_VALUE"""),1.0) -> 1 | O4: =IFERROR(__xludf.DUMMYFUNCTION("""COMPUTED_VALUE"""),3.0) -> 3
A5: ='アセスメント'!B6 -> TEAM-1-4 | B5: =criteria!D5 -> プラクティス | C5: ='アセスメント'!F6 -> FALSE | D5: ='アセスメント'!G6 -> FALSE | E5: ='アセスメント'!H6 -> FALSE | F5: =not(and(C5,D5)) -> TRUE | G5: =or(C5,D5) -> FALSE | H5: =and(G5,not(F5)) -> FALSE | I5: =and(G5,F5) -> FALSE | J5: =if(B5="アンチパターン",true,false) -> FALSE | K5: =if(E5,0.5,if(C5,1,0)) -> 0 | L5: =if(H5,"@" ,if(G5, if(J5,1-K5,K5),"-")) -> - | M5: =IFERROR(__xludf.DUMMYFUNCTION("split(A5,""-"")"),"TEAM") -> TEAM | N5: =IFERROR(__xludf.DUMMYFUNCTION("""COMPUTED_VALUE"""),1.0) -> 1 | O5: =IFERROR(__xludf.DUMMYFUNCTION("""COMPUTED_VALUE"""),4.0) -> 4
A6: ='アセスメント'!B7 -> TEAM-1-5 | B6: =criteria!D6 -> プラクティス | C6: ='アセスメント'!F7 -> FALSE | D6: ='アセスメント'!G7 -> FALSE | E6: ='アセスメント'!H7 -> FALSE | F6: =not(and(C6,D6)) -> TRUE | G6: =or(C6,D6) -> FALSE | H6: =and(G6,not(F6)) -> FALSE | I6: =and(G6,F6) -> FALSE | J6: =if(B6="アンチパターン",true,false) -> FALSE | K6: =if(E6,0.5,if(C6,1,0)) -> 0 | L6: =if(H6,"@" ,if(G6, if(J6,1-K6,K6),"-")) -> - | M6: =IFERROR(__xludf.DUMMYFUNCTION("split(A6,""-"")"),"TEAM") -> TEAM | N6: =IFERROR(__xludf.DUMMYFUNCTION("""COMPUTED_VALUE"""),1.0) -> 1 | O6: =IFERROR(__xludf.DUMMYFUNCTION("""COMPUTED_VALUE"""),5.0) -> 5
A7: ='アセスメント'!B8 -> TEAM-1-6 | B7: =criteria!D7 -> アンチパターン | C7: ='アセスメント'!F8 -> FALSE | D7: ='アセスメント'!G8 -> FALSE | E7: ='アセスメント'!H8 -> FALSE | F7: =not(and(C7,D7)) -> TRUE | G7: =or(C7,D7) -> FALSE | H7: =and(G7,not(F7)) -> FALSE | I7: =and(G7,F7) -> FALSE | J7: =if(B7="アンチパターン",true,false) -> TRUE | K7: =if(E7,0.5,if(C7,1,0)) -> 0 | L7: =if(H7,"@" ,if(G7, if(J7,1-K7,K7),"-")) -> - | M7: =IFERROR(__xludf.DUMMYFUNCTION("split(A7,""-"")"),"TEAM") -> TEAM | N7: =IFERROR(__xludf.DUMMYFUNCTION("""COMPUTED_VALUE"""),1.0) -> 1 | O7: =IFERROR(__xludf.DUMMYFUNCTION("""COMPUTED_VALUE"""),6.0) -> 6
A8: ='アセスメント'!B9 -> TEAM-1-7 | B8: =criteria!D8 -> アンチパターン | C8: ='アセスメント'!F9 -> FALSE | D8: ='アセスメント'!G9 -> FALSE | E8: ='アセスメント'!H9 -> FALSE | F8: =not(and(C8,D8)) -> TRUE | G8: =or(C8,D8) -> FALSE | H8: =and(G8,not(F8)) -> FALSE | I8: =and(G8,F8) -> FALSE | J8: =if(B8="アンチパターン",true,false) -> TRUE | K8: =if(E8,0.5,if(C8,1,0)) -> 0 | L8: =if(H8,"@" ,if(G8, if(J8,1-K8,K8),"-")) -> - | M8: =IFERROR(__xludf.DUMMYFUNCTION("split(A8,""-"")"),"TEAM") -> TEAM | N8: =IFERROR(__xludf.DUMMYFUNCTION("""COMPUTED_VALUE"""),1.0) -> 1 | O8: =IFERROR(__xludf.DUMMYFUNCTION("""COMPUTED_VALUE"""),7.0) -> 7
A9: ='アセスメント'!B10 -> TEAM-1-8 | B9: =criteria!D9 -> アンチパターン | C9: ='アセスメント'!F10 -> FALSE | D9: ='アセスメント'!G10 -> FALSE | E9: ='アセスメント'!H10 -> FALSE | F9: =not(and(C9,D9)) -> TRUE | G9: =or(C9,D9) -> FALSE | H9: =and(G9,not(F9)) -> FALSE | I9: =and(G9,F9) -> FALSE | J9: =if(B9="アンチパターン",true,false) -> TRUE | K9: =if(E9,0.5,if(C9,1,0)) -> 0 | L9: =if(H9,"@" ,if(G9, if(J9,1-K9,K9),"-")) -> - | M9: =IFERROR(__xludf.DUMMYFUNCTION("split(A9,""-"")"),"TEAM") -> TEAM | N9: =IFERROR(__xludf.DUMMYFUNCTION("""COMPUTED_VALUE"""),1.0) -> 1 | O9: =IFERROR(__xludf.DUMMYFUNCTION("""COMPUTED_VALUE"""),8.0) -> 8
